Workbook
Name PAR_FECHA_INICIO: CONFIG!$B$8
Name PAR_MESES: CONFIG!$B$9
Name PAR_SALDO_CAJA: CONFIG!$B$10
Name PAR_CAPITAL_INICIAL: CONFIG!$B$11
Name PAR_DIAS_MES: CONFIG!$B$12
Name PAR_ISV: CONFIG!$B$14
Name PAR_ALERTA_STOCK: CONFIG!$B$16
Name PAR_MARGEN_OBJ: CONFIG!$B$17
Name LISTA_CATEGORIAS: OFFSET(CONFIG!$B$23,0,0,MAX(1,COUNTA(CONFIG!$B$23:$B$83)),1)
Name LISTA_SUBCATEGORIAS: OFFSET(CONFIG!$C$23,0,0,MAX(1,COUNTA(CONFIG!$C$23:$C$83)),1)
Name LISTA_PRESENTACIONES: OFFSET(CONFIG!$D$23,0,0,MAX(1,COUNTA(CONFIG!$D$23:$D$83)),1)
Name LISTA_UNIDADES: OFFSET(CONFIG!$E$23,0,0,MAX(1,COUNTA(CONFIG!$E$23:$E$83)),1)
Name LISTA_CANALES: OFFSET(CONFIG!$F$23,0,0,MAX(1,COUNTA(CONFIG!$F$23:$F$83)),1)
Name LISTA_METODOS_PAGO: OFFSET(CONFIG!$G$23,0,0,MAX(1,COUNTA(CONFIG!$G$23:$G$83)),1)
Name LISTA_TIPO_GASTO: OFFSET(CONFIG!$H$23,0,0,MAX(1,COUNTA(CONFIG!$H$23:$H$83)),1)
Name LISTA_CAT_GASTO: OFFSET(CONFIG!$I$23,0,0,MAX(1,COUNTA(CONFIG!$I$23:$I$83)),1)
Name LISTA_ESTADO_PRODUCTO: OFFSET(CONFIG!$J$23,0,0,MAX(1,COUNTA(CONFIG!$J$23:$J$83)),1)
Name LISTA_ESTADO_PAGO: OFFSET(CONFIG!$K$23,0,0,MAX(1,COUNTA(CONFIG!$K$23:$K$83)),1)
Name LISTA_ESTADO_REL: OFFSET(CONFIG!$L$23,0,0,MAX(1,COUNTA(CONFIG!$L$23:$L$83)),1)
Name LISTA_CONCEPTO_CAJA: OFFSET(CONFIG!$M$23,0,0,MAX(1,COUNTA(CONFIG!$M$23:$M$83)),1)
Name LISTA_CONDICIONES: OFFSET(CONFIG!$N$23,0,0,MAX(1,COUNTA(CONFIG!$N$23:$N$83)),1)
Name LISTA_SINO: OFFSET(CONFIG!$O$23,0,0,MAX(1,COUNTA(CONFIG!$O$23:$O$83)),1)
Name LISTA_MODO: OFFSET(CONFIG!$P$23,0,0,MAX(1,COUNTA(CONFIG!$P$23:$P$83)),1)
Name LISTA_TIPO_MOV: OFFSET(CONFIG!$Q$23,0,0,MAX(1,COUNTA(CONFIG!$Q$23:$Q$83)),1)
Name LISTA_SKU: OFFSET(PRODUCTOS!$A$7,0,0,MAX(1,COUNTA(PRODUCTOS!$A$7:$A$66)),1)
Name LISTA_CLIENTES: OFFSET(CLIENTES!$B$7,0,0,MAX(1,COUNTA(CLIENTES!$B$7:$B$156)),1)
Name LISTA_PROVEEDORES: OFFSET(PROVEEDORES!$B$7,0,0,MAX(1,COUNTA(PROVEEDORES!$B$7:$B$46)),1)
Name LISTA_MESES: RENTABILIDAD!$A$8:$A$43

Sheet INICIO
B1: AROMATIC · Sistema Financiero y de Gestión Comercial
B2: Guía de uso. Léala una vez y tendrá el control total del sistema.
B4: ¿QUÉ ES ESTE ARCHIVO?
B5: En una frase | C5: Es el centro financiero de AROMATIC: registra productos, costos, compras, ventas y gastos, y a partir de eso calcula solo su inventario, su utilidad, su efectivo, su punto de equilibrio y sus metas.
B6: Lo más importante | C6: Usted solo escribe en las celdas AMARILLAS. Todo lo demás se calcula. Nunca borre una fórmula: si se equivoca, pulse Ctrl+Z.
B7: Precios del catálogo | C7: El catálogo 2016 se usó únicamente para cargar los 40 productos con sus nombres, categorías y presentaciones. Sus precios quedaron guardados aparte, en la columna «Precio de referencia del catálogo 2016», que es informativa y NO entra en ningún cálculo. El sistema trabaja exclusivamente con «Precio de venta actual», que está vacío hasta que usted lo defina.
B8: Nada inventado | C8: No hay ni un solo precio, costo, margen o proyección inventado. Donde falta información el sistema dice PENDIENTE en lugar de mostrar un número falso o un error de Excel.
B10: CÓDIGO DE COLORES
B11: Amarillo | C11: Celda de captura: usted escribe aquí.
B12: Gris claro | C12: Celda calculada: no la toque, contiene una fórmula.
B13: Verde claro | C13: Se llena sola, pero usted puede sobrescribirla en un caso puntual (por ejemplo, el precio de una venta con condiciones especiales).
B14: Gris con letra cursiva | C14: Dato informativo del catálogo 2016. No se usa en ningún cálculo.
B15: Rojo / Ámbar | C15: Alertas automáticas: algo está mal o requiere su atención.
B17: MAPA DE HOJAS
B18: Hoja | C18: Para qué sirve · ¿se escribe en ella?
B19: DASHBOARD | C19: Tablero con los números clave del mes y del negocio. → ¿Escribe usted aquí?: No se escribe (solo el mes)
B20: PRODUCTOS | C20: Catálogo maestro: un SKU por fila, con precio, stock mínimo y máximo. → ¿Escribe usted aquí?: SÍ
B21: COSTOS | C21: Todos los costos de cada producto: compra, transporte, impuestos, empaque, comisiones. → ¿Escribe usted aquí?: SÍ
B22: COMPRAS | C22: Lo que usted le compra a sus proveedores. Aumenta el inventario. → ¿Escribe usted aquí?: SÍ
B23: INVENTARIO | C23: Existencias y valor del inventario. Se calcula solo. → ¿Escribe usted aquí?: Solo stock inicial y ajustes
B24: VENTAS | C24: Cada venta, línea por línea. Disminuye el inventario. → ¿Escribe usted aquí?: SÍ
B25: GASTOS | C25: Gastos del negocio, separados en fijos y variables. → ¿Escribe usted aquí?: SÍ
B26: CAJA | C26: Entradas y salidas de dinero real, mes por mes. → ¿Escribe usted aquí?: Solo aportes, retiros y otros movimientos
B27: CLIENTES | C27: Base de clientes con su historial de compras. → ¿Escribe usted aquí?: SÍ
B28: PROVEEDORES | C28: Base de proveedores con condiciones y saldos. → ¿Escribe usted aquí?: SÍ
B29: RENTABILIDAD | C29: Estado de resultados mensual y análisis por producto, categoría y canal. → ¿Escribe usted aquí?: No
... B34: CONFIG | C34: Moneda, categorías, canales, métodos de pago y demás listas del sistema. → ¿Escribe usted aquí?: SÍ
B36: PRIMEROS PASOS (hágalos en este orden)
C37: 1. Vaya a CONFIG y escriba su saldo inicial de caja, su capital aportado y la fecha de inicio del calendario.
C38: 2. Vaya a PROVEEDORES y registre a quién le compra (el nombre es la llave del sistema).
C39: 3. Vaya a COSTOS y escriba, para cada producto que ya vende, cuánto le cuesta: compra, transporte, impuestos, empaque. Si algo no aplica, déjelo vacío.
C40: 4. Vaya a PRODUCTOS y escriba el «Precio de venta actual» de cada producto. En ese momento el sistema calcula su utilidad, su margen y su markup.
C41: 5. Vaya a INVENTARIO y escriba el «Stock inicial» que tiene hoy de cada producto.
C42: 6. Registre sus COMPRAS y sus VENTAS conforme vayan ocurriendo.
C43: 7. Registre sus GASTOS (alquiler, internet, publicidad, transporte…).
C44: 8. Revise la hoja CONTROL: si aparece algún problema, corríjalo. Luego abra el DASHBOARD.
B46: CÓMO HACER CADA COSA
B47: Agregar un producto nuevo | C47: 1) En PRODUCTOS, escriba en la primera fila vacía: SKU (código único, por ejemplo GEL-250), nombre, categoría, presentación y unidad. 2) En COSTOS, agregue una fila con ese mismo SKU y capture sus costos. 3) Vuelva a PRODUCTOS y escriba el precio de venta actual. El inventario y todos los análisis lo incluirán automáticamente.
B48: Definir o cambiar un precio | C48: En PRODUCTOS, columna «Precio de venta actual». Es el ÚNICO precio que usa el sistema. Al cambiarlo se recalculan utilidad, margen, markup, margen de contribución y punto de equilibrio.
B49: Registrar una compra | C49: En COMPRAS: fecha, proveedor, SKU, cantidad y costo unitario. Agregue transporte, impuestos y otros costos si los hubo: el sistema calcula el costo real de adquisición y actualiza el costo promedio ponderado del inventario. Si ya pagó, escriba la fecha de pago y el monto pagado.
...

Sheet DASHBOARD
B1: AROMATIC · TABLERO FINANCIERO
B2: Todo lo que ve aquí se calcula solo. Cambie el mes en la celda amarilla para analizar otro período.
B4: Mes en análisis: | C4: 46266 | E4: ← seleccione el mes | G4: =IF(CONTROL!$B$4=0,"✓ Datos sin problemas pendientes","⚠ "&TEXT(CONTROL!$B$4,"0")&" dato(s) pendiente(s) o problema(s) detectado(s) — vea la hoja CONTROL")
B6: VENTAS DEL MES SELECCIONADO
B7: Ventas netas | E7: Unidades vendidas | H7: Ticket promedio | K7: Transacciones
B8: =IFERROR(INDEX(RENTABILIDAD!$D$8:$D$43,MATCH($C$4,RENTABILIDAD!$A$8:$A$43,0)),"") | E8: =IFERROR(INDEX(RENTABILIDAD!$E$8:$E$43,MATCH($C$4,RENTABILIDAD!$A$8:$A$43,0)),"") | H8: =IFERROR(INDEX(RENTABILIDAD!$R$8:$R$43,MATCH($C$4,RENTABILIDAD!$A$8:$A$43,0)),"") | K8: =IFERROR(INDEX(RENTABILIDAD!$Q$8:$Q$43,MATCH($C$4,RENTABILIDAD!$A$8:$A$43,0)),"")
B10: RENTABILIDAD DEL MES
B11: Utilidad bruta | E11: Margen bruto | H11: Utilidad neta | K11: Margen neto
B12: =IFERROR(INDEX(RENTABILIDAD!$G$8:$G$43,MATCH($C$4,RENTABILIDAD!$A$8:$A$43,0)),"") | E12: =IFERROR(INDEX(RENTABILIDAD!$H$8:$H$43,MATCH($C$4,RENTABILIDAD!$A$8:$A$43,0)),"") | H12: =IFERROR(INDEX(RENTABILIDAD!$O$8:$O$43,MATCH($C$4,RENTABILIDAD!$A$8:$A$43,0)),"") | K12: =IFERROR(INDEX(RENTABILIDAD!$P$8:$P$43,MATCH($C$4,RENTABILIDAD!$A$8:$A$43,0)),"")
B14: ACUMULADO DEL NEGOCIO
B15: Ventas acumuladas | E15: Utilidad neta acumulada | H15: ROI sobre la inversión | K15: Margen neto acumulado
B16: =RENTABILIDAD!$D$44 | E16: =RENTABILIDAD!$O$44 | H16: =RENTABILIDAD!$BK$26 | K16: =RENTABILIDAD!$P$44
B18: INVENTARIO Y CAPITAL
B19: Valor del inventario | E19: Productos con stock bajo | H19: Productos agotados | K19: Capital de trabajo comprometido
B20: =RENTABILIDAD!$BK$29 | E20: =COUNTIF(tblInventario[ESTADO],"REABASTECER") | H20: =COUNTIF(tblInventario[ESTADO],"AGOTADO") | K20: =RENTABILIDAD!$BK$32
B22: EFECTIVO DEL MES
B23: Entradas de efectivo | E23: Salidas de efectivo | H23: Flujo neto del mes | K23: Saldo disponible al cierre
B24: =IFERROR(INDEX(CAJA!$G$7:$G$42,MATCH($C$4,RENTABILIDAD!$A$8:$A$43,0)),"") | E24: =IFERROR(INDEX(CAJA!$M$7:$M$42,MATCH($C$4,RENTABILIDAD!$A$8:$A$43,0)),"") | H24: =IFERROR(INDEX(CAJA!$N$7:$N$42,MATCH($C$4,RENTABILIDAD!$A$8:$A$43,0)),"") | K24: =IFERROR(INDEX(CAJA!$O$7:$O$42,MATCH($C$4,RENTABILIDAD!$A$8:$A$43,0)),"")
B26: CUMPLIMIENTO DE METAS DEL MES
B27: Cumplimiento de ventas | E27: Cumplimiento de utilidad | H27: Cumplimiento de unidades | K27: Estado del mes
B28: =IFERROR(INDEX(METAS!$L$7:$L$42,MATCH($C$4,RENTABILIDAD!$A$8:$A$43,0)),"") | E28: =IFERROR(INDEX(METAS!$M$7:$M$42,MATCH($C$4,RENTABILIDAD!$A$8:$A$43,0)),"") | H28: =IFERROR(INDEX(METAS!$N$7:$N$42,MATCH($C$4,RENTABILIDAD!$A$8:$A$43,0)),"") | K28: =IFERROR(INDEX(METAS!$W$7:$W$42,MATCH($C$4,RENTABILIDAD!$A$8:$A$43,0)),"")
B30: INDICADORES FINANCIEROS CLAVE
B31: Punto de equilibrio (unidades/mes) | E31: Punto de equilibrio (Lempiras/mes) | H31: Margen de contribución % | K31: Cuentas por cobrar
B32: =EQUILIBRIO!$B$16 | E32: =EQUILIBRIO!$B$17 | H32: =EQUILIBRIO!$B$15 | K32: =RENTABILIDAD!$BK$30
P34: Datos auxiliares de los gráficos (no editar)
P35: Producto (utilidad) | Q35: Utilidad | S35: Producto (unidades) | T35: Unidades
P36: =IFERROR(IF(LARGE(RENTABILIDAD!$AO$8:$AO$67,1)<=0,"",INDEX(RENTABILIDAD!$AB$8:$AB$67,MATCH(LARGE(RENTABILIDAD!$AO$8:$AO$67,1),RENTABILIDAD!$AO$8:$AO$67,0))),"") | Q36: =IFERROR(IF(LARGE(RENTABILIDAD!$AO$8:$AO$67,1)<=0,"",INDEX(RENTABILIDAD!$AG$8:$AG$67,MATCH(LARGE(RENTABILIDAD!$AO$8:$AO$67,1),RENTABILIDAD!$AO$8:$AO$67,0))),"") | S36: =IFERROR(IF(LARGE(RENTABILIDAD!$AP$8:$AP$67,1)<=0,"",INDEX(RENTABILIDAD!$AB$8:$AB$67,MATCH(LARGE(RENTABILIDAD!$AP$8:$AP$67,1),RENTABILIDAD!$AP$8:$AP$67,0))),"") | T36: =IFERROR(IF(LARGE(RENTABILIDAD!$AP$8:$AP$67,1)<=0,"",INDEX(RENTABILIDAD!$AD$8:$AD$67,MATCH(LARGE(RENTABILIDAD!$AP$8:$AP$67,1),RENTABILIDAD!$AP$8:$AP$67,0))),"")
P37: =IFERROR(IF(LARGE(RENTABILIDAD!$AO$8:$AO$67,2)<=0,"",INDEX(RENTABILIDAD!$AB$8:$AB$67,MATCH(LARGE(RENTABILIDAD!$AO$8:$AO$67,2),RENTABILIDAD!$AO$8:$AO$67,0))),"") | Q37: =IFERROR(IF(LARGE(RENTABILIDAD!$AO$8:$AO$67,2)<=0,"",INDEX(RENTABILIDAD!$AG$8:$AG$67,MATCH(LARGE(RENTABILIDAD!$AO$8:$AO$67,2),RENTABILIDAD!$AO$8:$AO$67,0))),"") | S37: =IFERROR(IF(LARGE(RENTABILIDAD!$AP$8:$AP$67,2)<=0,"",INDEX(RENTABILIDAD!$AB$8:$AB$67,MATCH(LARGE(RENTABILIDAD!$AP$8:$AP$67,2),RENTABILIDAD!$AP$8:$AP$67,0))),"") | T37: =IFERROR(IF(LARGE(RENTABILIDAD!$AP$8:$AP$67,2)<=0,"",INDEX(RENTABILIDAD!$AD$8:$AD$67,MATCH(LARGE(RENTABILIDAD!$AP$8:$AP$67,2),RENTABILIDAD!$AP$8:$AP$67,0))),"")
P38: =IFERROR(IF(LARGE(RENTABILIDAD!$AO$8:$AO$67,3)<=0,"",INDEX(RENTABILIDAD!$AB$8:$AB$67,MATCH(LARGE(RENTABILIDAD!$AO$8:$AO$67,3),RENTABILIDAD!$AO$8:$AO$67,0))),"") | Q38: =IFERROR(IF(LARGE(RENTABILIDAD!$AO$8:$AO$67,3)<=0,"",INDEX(RENTABILIDAD!$AG$8:$AG$67,MATCH(LARGE(RENTABILIDAD!$AO$8:$AO$67,3),RENTABILIDAD!$AO$8:$AO$67,0))),"") | S38: =IFERROR(IF(LARGE(RENTABILIDAD!$AP$8:$AP$67,3)<=0,"",INDEX(RENTABILIDAD!$AB$8:$AB$67,MATCH(LARGE(RENTABILIDAD!$AP$8:$AP$67,3),RENTABILIDAD!$AP$8:$AP$67,0))),"") | T38: =IFERROR(IF(LARGE(RENTABILIDAD!$AP$8:$AP$67,3)<=0,"",INDEX(RENTABILIDAD!$AD$8:$AD$67,MATCH(LARGE(RENTABILIDAD!$AP$8:$AP$67,3),RENTABILIDAD!$AP$8:$AP$67,0))),"")
P39: =IFERROR(IF(LARGE(RENTABILIDAD!$AO$8:$AO$67,4)<=0,"",INDEX(RENTABILIDAD!$AB$8:$AB$67,MATCH(LARGE(RENTABILIDAD!$AO$8:$AO$67,4),RENTABILIDAD!$AO$8:$AO$67,0))),"") | Q39: =IFERROR(IF(LARGE(RENTABILIDAD!$AO$8:$AO$67,4)<=0,"",INDEX(RENTABILIDAD!$AG$8:$AG$67,MATCH(LARGE(RENTABILIDAD!$AO$8:$AO$67,4),RENTABILIDAD!$AO$8:$AO$67,0))),"") | S39: =IFERROR(IF(LARGE(RENTABILIDAD!$AP$8:$AP$67,4)<=0,"",INDEX(RENTABILIDAD!$AB$8:$AB$67,MATCH(LARGE(RENTABILIDAD!$AP$8:$AP$67,4),RENTABILIDAD!$AP$8:$AP$67,0))),"") | T39: =IFERROR(IF(LARGE(RENTABILIDAD!$AP$8:$AP$67,4)<=0,"",INDEX(RENTABILIDAD!$AD$8:$AD$67,MATCH(LARGE(RENTABILIDAD!$AP$8:$AP$67,4),RENTABILIDAD!$AP$8:$AP$67,0))),"")
P40: =IFERROR(IF(LARGE(RENTABILIDAD!$AO$8:$AO$67,5)<=0,"",INDEX(RENTABILIDAD!$AB$8:$AB$67,MATCH(LARGE(RENTABILIDAD!$AO$8:$AO$67,5),RENTABILIDAD!$AO$8:$AO$67,0))),"") | Q40: =IFERROR(IF(LARGE(RENTABILIDAD!$AO$8:$AO$67,5)<=0,"",INDEX(RENTABILIDAD!$AG$8:$AG$67,MATCH(LARGE(RENTABILIDAD!$AO$8:$AO$67,5),RENTABILIDAD!$AO$8:$AO$67,0))),"") | S40: =IFERROR(IF(LARGE(RENTABILIDAD!$AP$8:$AP$67,5)<=0,"",INDEX(RENTABILIDAD!$AB$8:$AB$67,MATCH(LARGE(RENTABILIDAD!$AP$8:$AP$67,5),RENTABILIDAD!$AP$8:$AP$67,0))),"") | T40: =IFERROR(IF(LARGE(RENTABILIDAD!$AP$8:$AP$67,5)<=0,"",INDEX(RENTABILIDAD!$AD$8:$AD$67,MATCH(LARGE(RENTABILIDAD!$AP$8:$AP$67,5),RENTABILIDAD!$AP$8:$AP$67,0))),"")
P41: =IFERROR(IF(LARGE(RENTABILIDAD!$AO$8:$AO$67,6)<=0,"",INDEX(RENTABILIDAD!$AB$8:$AB$67,MATCH(LARGE(RENTABILIDAD!$AO$8:$AO$67,6),RENTABILIDAD!$AO$8:$AO$67,0))),"") | Q41: =IFERROR(IF(LARGE(RENTABILIDAD!$AO$8:$AO$67,6)<=0,"",INDEX(RENTABILIDAD!$AG$8:$AG$67,MATCH(LARGE(RENTABILIDAD!$AO$8:$AO$67,6),RENTABILIDAD!$AO$8:$AO$67,0))),"") | S41: =IFERROR(IF(LARGE(RENTABILIDAD!$AP$8:$AP$67,6)<=0,"",INDEX(RENTABILIDAD!$AB$8:$AB$67,MATCH(LARGE(RENTABILIDAD!$AP$8:$AP$67,6),RENTABILIDAD!$AP$8:$AP$67,0))),"") | T41: =IFERROR(IF(LARGE(RENTABILIDAD!$AP$8:$AP$67,6)<=0,"",INDEX(RENTABILIDAD!$AD$8:$AD$67,MATCH(LARGE(RENTABILIDAD!$AP$8:$AP$67,6),RENTABILIDAD!$AP$8:$AP$67,0))),"")
P42: =IFERROR(IF(LARGE(RENTABILIDAD!$AO$8:$AO$67,7)<=0,"",INDEX(RENTABILIDAD!$AB$8:$AB$67,MATCH(LARGE(RENTABILIDAD!$AO$8:$AO$67,7),RENTABILIDAD!$AO$8:$AO$67,0))),"") | Q42: =IFERROR(IF(LARGE(RENTABILIDAD!$AO$8:$AO$67,7)<=0,"",INDEX(RENTABILIDAD!$AG$8:$AG$67,MATCH(LARGE(RENTABILIDAD!$AO$8:$AO$67,7),RENTABILIDAD!$AO$8:$AO$67,0))),"") | S42: =IFERROR(IF(LARGE(RENTABILIDAD!$AP$8:$AP$67,7)<=0,"",INDEX(RENTABILIDAD!$AB$8:$AB$67,MATCH(LARGE(RENTABILIDAD!$AP$8:$AP$67,7),RENTABILIDAD!$AP$8:$AP$67,0))),"") | T42: =IFERROR(IF(LARGE(RENTABILIDAD!$AP$8:$AP$67,7)<=0,"",INDEX(RENTABILIDAD!$AD$8:$AD$67,MATCH(LARGE(RENTABILIDAD!$AP$8:$AP$67,7),RENTABILIDAD!$AP$8:$AP$67,0))),"")
P43: =IFERROR(IF(LARGE(RENTABILIDAD!$AO$8:$AO$67,8)<=0,"",INDEX(RENTABILIDAD!$AB$8:$AB$67,MATCH(LARGE(RENTABILIDAD!$AO$8:$AO$67,8),RENTABILIDAD!$AO$8:$AO$67,0))),"") | Q43: =IFERROR(IF(LARGE(RENTABILIDAD!$AO$8:$AO$67,8)<=0,"",INDEX(RENTABILIDAD!$AG$8:$AG$67,MATCH(LARGE(RENTABILIDAD!$AO$8:$AO$67,8),RENTABILIDAD!$AO$8:$AO$67,0))),"") | S43: =IFERROR(IF(LARGE(RENTABILIDAD!$AP$8:$AP$67,8)<=0,"",INDEX(RENTABILIDAD!$AB$8:$AB$67,MATCH(LARGE(RENTABILIDAD!$AP$8:$AP$67,8),RENTABILIDAD!$AP$8:$AP$67,0))),"") | T43: =IFERROR(IF(LARGE(RENTABILIDAD!$AP$8:$AP$67,8)<=0,"",INDEX(RENTABILIDAD!$AD$8:$AD$67,MATCH(LARGE(RENTABILIDAD!$AP$8:$AP$67,8),RENTABILIDAD!$AP$8:$AP$67,0))),"")
P44: =IFERROR(IF(LARGE(RENTABILIDAD!$AO$8:$AO$67,9)<=0,"",INDEX(RENTABILIDAD!$AB$8:$AB$67,MATCH(LARGE(RENTABILIDAD!$AO$8:$AO$67,9),RENTABILIDAD!$AO$8:$AO$67,0))),"") | Q44: =IFERROR(IF(LARGE(RENTABILIDAD!$AO$8:$AO$67,9)<=0,"",INDEX(RENTABILIDAD!$AG$8:$AG$67,MATCH(LARGE(RENTABILIDAD!$AO$8:$AO$67,9),RENTABILIDAD!$AO$8:$AO$67,0))),"") | S44: =IFERROR(IF(LARGE(RENTABILIDAD!$AP$8:$AP$67,9)<=0,"",INDEX(RENTABILIDAD!$AB$8:$AB$67,MATCH(LARGE(RENTABILIDAD!$AP$8:$AP$67,9),RENTABILIDAD!$AP$8:$AP$67,0))),"") | T44: =IFERROR(IF(LARGE(RENTABILIDAD!$AP$8:$AP$67,9)<=0,"",INDEX(RENTABILIDAD!$AD$8:$AD$67,MATCH(LARGE(RENTABILIDAD!$AP$8:$AP$67,9),RENTABILIDAD!$AP$8:$AP$67,0))),"")
P45: =IFERROR(IF(LARGE(RENTABILIDAD!$AO$8:$AO$67,10)<=0,"",INDEX(RENTABILIDAD!$AB$8:$AB$67,MATCH(LARGE(RENTABILIDAD!$AO$8:$AO$67,10),RENTABILIDAD!$AO$8:$AO$67,0))),"") | Q45: =IFERROR(IF(LARGE(RENTABILIDAD!$AO$8:$AO$67,10)<=0,"",INDEX(RENTABILIDAD!$AG$8:$AG$67,MATCH(LARGE(RENTABILIDAD!$AO$8:$AO$67,10),RENTABILIDAD!$AO$8:$AO$67,0))),"") | S45: =IFERROR(IF(LARGE(RENTABILIDAD!$AP$8:$AP$67,10)<=0,"",INDEX(RENTABILIDAD!$AB$8:$AB$67,MATCH(LARGE(RENTABILIDAD!$AP$8:$AP$67,10),RENTABILIDAD!$AP$8:$AP$67,0))),"") | T45: =IFERROR(IF(LARGE(RENTABILIDAD!$AP$8:$AP$67,10)<=0,"",INDEX(RENTABILIDAD!$AD$8:$AD$67,MATCH(LARGE(RENTABILIDAD!$AP$8:$AP$67,10),RENTABILIDAD!$AP$8:$AP$67,0))),"")
B88: Los gráficos se actualizan solos al registrar ventas, compras y gastos. Si un gráfico aparece vacío es porque todavía no hay datos de ese tipo.

Sheet PRODUCTOS
A1: PRODUCTOS — Catálogo maestro
A2: Una fila por SKU. Amarillo = usted lo escribe · Gris = lo calcula el sistema. Los costos se capturan en la hoja COSTOS y se reflejan aquí automáticamente.
A3: ⚠ REGLA DE PRECIOS: | B3: La columna «Precio de referencia del catálogo 2016» es SOLO INFORMATIVA y no entra en ningún cálculo. El sistema únicamente usa «Precio de venta actual», que nace vacío: usted debe escribirlo cuando defina sus precios reales.
A6: SKU | B6: Nombre del producto | C6: Categoría | D6: Subcategoría | E6: Presentación | F6: Unidad de medida | G6: Contenido (mL) | H6: Aromas disponibles | I6: Proveedor principal | J6: Precio de referencia del catálogo 2016 (INFORMATIVO) | K6: Precio de venta actual | L6: Costo de compra unitario | M6: Transporte unitario | N6: Impuestos / aranceles unitarios | O6: Empaque unitario | P6: Otros costos variables unitarios | Q6: COSTO REAL UNITARIO | R6: Costo variable de venta unitario | S6: Costo variable TOTAL unitario | T6: Utilidad unitaria | U6: Margen bruto % | V6: Markup % | W6: Margen de contribución unitario | X6: Stock actual | Y6: Stock mínimo | Z6: Stock máximo | AA6: Estado | AB6: Estado de datos | AC6: Fecha de actualización | AD6: Notas
A7: GEL-250 | B7: Gel Desinfectante Antibacterial | C7: Hogar | D7: Desinfección personal | E7: 250 mL | F7: Unidad | G7: 250 | H7: Original, Papaya, Fresa | J7: 35 | L7: =IF($A7="","",IFERROR(IF(INDEX(tblCostos[Costo de compra unitario],MATCH($A7,tblCostos[SKU],0))="","PENDIENTE",INDEX(tblCostos[Costo de compra unitario],MATCH($A7,tblCostos[SKU],0))),"PENDIENTE")) | M7: =IF($A7="","",IFERROR(IF(INDEX(tblCostos[Transporte unitario],MATCH($A7,tblCostos[SKU],0))="","",INDEX(tblCostos[Transporte unitario],MATCH($A7,tblCostos[SKU],0))),"")) | N7: =IF($A7="","",IFERROR(IF(INDEX(tblCostos[Impuestos / aranceles unitarios],MATCH($A7,tblCostos[SKU],0))="","",INDEX(tblCostos[Impuestos / aranceles unitarios],MATCH($A7,tblCostos[SKU],0))),"")) | O7: =IF($A7="","",IFERROR(IF(INDEX(tblCostos[Empaque unitario],MATCH($A7,tblCostos[SKU],0))="","",INDEX(tblCostos[Empaque unitario],MATCH($A7,tblCostos[SKU],0))),"")) | P7: =IF($A7="","",IFERROR(IF(INDEX(tblCostos[Otros costos variables unitarios],MATCH($A7,tblCostos[SKU],0))="","",INDEX(tblCostos[Otros costos variables unitarios],MATCH($A7,tblCostos[SKU],0))),"")) | Q7: =IF($A7="","",IFERROR(IF(INDEX(tblCostos[COSTO REAL UNITARIO],MATCH($A7,tblCostos[SKU],0))="","PENDIENTE",INDEX(tblCostos[COSTO REAL UNITARIO],MATCH($A7,tblCostos[SKU],0))),"PENDIENTE")) | R7: =IF($A7="","",IFERROR(IF(INDEX(tblCostos[Costo variable de venta unitario],MATCH($A7,tblCostos[SKU],0))="","",INDEX(tblCostos[Costo variable de venta unitario],MATCH($A7,tblCostos[SKU],0))),"")) | S7: =IF($A7="","",IF(NOT(ISNUMBER($Q7)),"PENDIENTE",$Q7+IF(ISNUMBER($R7),$R7,0))) | T7: =IF($A7="","",IF(OR($K7="",NOT(ISNUMBER($K7)),NOT(ISNUMBER($Q7))),"PENDIENTE",$K7-$Q7)) | U7: =IF($A7="","",IF(OR(NOT(ISNUMBER($T7)),NOT(ISNUMBER($K7)),$K7<=0),"PENDIENTE",$T7/$K7)) | V7: =IF($A7="","",IF(OR(NOT(ISNUMBER($T7)),NOT(ISNUMBER($Q7)),$Q7<=0),"PENDIENTE",$T7/$Q7)) | W7: =IF($A7="","",IF(OR($K7="",NOT(ISNUMBER($K7)),NOT(ISNUMBER($S7))),"PENDIENTE",$K7-$S7)) | X7: =IF($A7="","",IFERROR(INDEX(tblInventario[Stock actual],MATCH($A7,tblInventario[SKU],0)),0)) | AA7: Activo | AB7: =IF($A7="","",IF(COUNTIF(tblCostos[SKU],$A7)=0,"SIN FILA EN COSTOS",IF(AND($K7="",NOT(ISNUMBER($Q7))),"FALTA PRECIO Y COSTO",IF($K7="","FALTA PRECIO",IF(NOT(ISNUMBER($Q7)),"FALTA COSTO",IF($T7<0,"MARGEN NEGATIVO",IF($T7=0,"PRECIO = COSTO","COMPLETO")))))))
A8: GEL-500 | B8: Gel Desinfectante Antibacterial | C8: Hogar | D8: Desinfección personal | E8: 500 mL | F8: Unidad | G8: 500 | H8: Original, Papaya, Fresa | J8: 70 | L8: =IF($A8="","",IFERROR(IF(INDEX(tblCostos[Costo de compra unitario],MATCH($A8,tblCostos[SKU],0))="","PENDIENTE",INDEX(tblCostos[Costo de compra unitario],MATCH($A8,tblCostos[SKU],0))),"PENDIENTE")) | M8: =IF($A8="","",IFERROR(IF(INDEX(tblCostos[Transporte unitario],MATCH($A8,tblCostos[SKU],0))="","",INDEX(tblCostos[Transporte unitario],MATCH($A8,tblCostos[SKU],0))),"")) | N8: =IF($A8="","",IFERROR(IF(INDEX(tblCostos[Impuestos / aranceles unitarios],MATCH($A8,tblCostos[SKU],0))="","",INDEX(tblCostos[Impuestos / aranceles unitarios],MATCH($A8,tblCostos[SKU],0))),"")) | O8: =IF($A8="","",IFERROR(IF(INDEX(tblCostos[Empaque unitario],MATCH($A8,tblCostos[SKU],0))="","",INDEX(tblCostos[Empaque unitario],MATCH($A8,tblCostos[SKU],0))),"")) | P8: =IF($A8="","",IFERROR(IF(INDEX(tblCostos[Otros costos variables unitarios],MATCH($A8,tblCostos[SKU],0))="","",INDEX(tblCostos[Otros costos variables unitarios],MATCH($A8,tblCostos[SKU],0))),"")) | Q8: =IF($A8="","",IFERROR(IF(INDEX(tblCostos[COSTO REAL UNITARIO],MATCH($A8,tblCostos[SKU],0))="","PENDIENTE",INDEX(tblCostos[COSTO REAL UNITARIO],MATCH($A8,tblCostos[SKU],0))),"PENDIENTE")) | R8: =IF($A8="","",IFERROR(IF(INDEX(tblCostos[Costo variable de venta unitario],MATCH($A8,tblCostos[SKU],0))="","",INDEX(tblCostos[Costo variable de venta unitario],MATCH($A8,tblCostos[SKU],0))),"")) | S8: =IF($A8="","",IF(NOT(ISNUMBER($Q8)),"PENDIENTE",$Q8+IF(ISNUMBER($R8),$R8,0))) | T8: =IF($A8="","",IF(OR($K8="",NOT(ISNUMBER($K8)),NOT(ISNUMBER($Q8))),"PENDIENTE",$K8-$Q8)) | U8: =IF($A8="","",IF(OR(NOT(ISNUMBER($T8)),NOT(ISNUMBER($K8)),$K8<=0),"PENDIENTE",$T8/$K8)) | V8: =IF($A8="","",IF(OR(NOT(ISNUMBER($T8)),NOT(ISNUMBER($Q8)),$Q8<=0),"PENDIENTE",$T8/$Q8)) | W8: =IF($A8="","",IF(OR($K8="",NOT(ISNUMBER($K8)),NOT(ISNUMBER($S8))),"PENDIENTE",$K8-$S8)) | X8: =IF($A8="","",IFERROR(INDEX(tblInventario[Stock actual],MATCH($A8,tblInventario[SKU],0)),0)) | AA8: Activo | AB8: =IF($A8="","",IF(COUNTIF(tblCostos[SKU],$A8)=0,"SIN FILA EN COSTOS",IF(AND($K8="",NOT(ISNUMBER($Q8))),"FALTA PRECIO Y COSTO",IF($K8="","FALTA PRECIO",IF(NOT(ISNUMBER($Q8)),"FALTA COSTO",IF($T8<0,"MARGEN NEGATIVO",IF($T8=0,"PRECIO = COSTO","COMPLETO")))))))
A9: GEL-2L | B9: Gel Desinfectante Antibacterial | C9: Hogar | D9: Desinfección personal | E9: 2 Litros | F9: Unidad | G9: 2000 | H9: Original, Papaya, Fresa | J9: 140 | L9: =IF($A9="","",IFERROR(IF(INDEX(tblCostos[Costo de compra unitario],MATCH($A9,tblCostos[SKU],0))="","PENDIENTE",INDEX(tblCostos[Costo de compra unitario],MATCH($A9,tblCostos[SKU],0))),"PENDIENTE")) | M9: =IF($A9="","",IFERROR(IF(INDEX(tblCostos[Transporte unitario],MATCH($A9,tblCostos[SKU],0))="","",INDEX(tblCostos[Transporte unitario],MATCH($A9,tblCostos[SKU],0))),"")) | N9: =IF($A9="","",IFERROR(IF(INDEX(tblCostos[Impuestos / aranceles unitarios],MATCH($A9,tblCostos[SKU],0))="","",INDEX(tblCostos[Impuestos / aranceles unitarios],MATCH($A9,tblCostos[SKU],0))),"")) | O9: =IF($A9="","",IFERROR(IF(INDEX(tblCostos[Empaque unitario],MATCH($A9,tblCostos[SKU],0))="","",INDEX(tblCostos[Empaque unitario],MATCH($A9,tblCostos[SKU],0))),"")) | P9: =IF($A9="","",IFERROR(IF(INDEX(tblCostos[Otros costos variables unitarios],MATCH($A9,tblCostos[SKU],0))="","",INDEX(tblCostos[Otros costos variables unitarios],MATCH($A9,tblCostos[SKU],0))),"")) | Q9: =IF($A9="","",IFERROR(IF(INDEX(tblCostos[COSTO REAL UNITARIO],MATCH($A9,tblCostos[SKU],0))="","PENDIENTE",INDEX(tblCostos[COSTO REAL UNITARIO],MATCH($A9,tblCostos[SKU],0))),"PENDIENTE")) | R9: =IF($A9="","",IFERROR(IF(INDEX(tblCostos[Costo variable de venta unitario],MATCH($A9,tblCostos[SKU],0))="","",INDEX(tblCostos[Costo variable de venta unitario],MATCH($A9,tblCostos[SKU],0))),"")) | S9: =IF($A9="","",IF(NOT(ISNUMBER($Q9)),"PENDIENTE",$Q9+IF(ISNUMBER($R9),$R9,0))) | T9: =IF($A9="","",IF(OR($K9="",NOT(ISNUMBER($K9)),NOT(ISNUMBER($Q9))),"PENDIENTE",$K9-$Q9)) | U9: =IF($A9="","",IF(OR(NOT(ISNUMBER($T9)),NOT(ISNUMBER($K9)),$K9<=0),"PENDIENTE",$T9/$K9)) | V9: =IF($A9="","",IF(OR(NOT(ISNUMBER($T9)),NOT(ISNUMBER($Q9)),$Q9<=0),"PENDIENTE",$T9/$Q9)) | W9: =IF($A9="","",IF(OR($K9="",NOT(ISNUMBER($K9)),NOT(ISNUMBER($S9))),"PENDIENTE",$K9-$S9)) | X9: =IF($A9="","",IFERROR(INDEX(tblInventario[Stock actual],MATCH($A9,tblInventario[SKU],0)),0)) | AA9: Activo | AB9: =IF($A9="","",IF(COUNTIF(tblCostos[SKU],$A9)=0,"SIN FILA EN COSTOS",IF(AND($K9="",NOT(ISNUMBER($Q9))),"FALTA PRECIO Y COSTO",IF($K9="","FALTA PRECIO",IF(NOT(ISNUMBER($Q9)),"FALTA COSTO",IF($T9<0,"MARGEN NEGATIVO",IF($T9=0,"PRECIO = COSTO","COMPLETO")))))))
A10: GEL-GAL | B10: Gel Desinfectante Antibacterial | C10: Hogar | D10: Desinfección personal | E10: Galón | F10: Unidad | G10: 3785 | H10: Original, Papaya, Fresa | J10: 330 | L10: =IF($A10="","",IFERROR(IF(INDEX(tblCostos[Costo de compra unitario],MATCH($A10,tblCostos[SKU],0))="","PENDIENTE",INDEX(tblCostos[Costo de compra unitario],MATCH($A10,tblCostos[SKU],0))),"PENDIENTE")) | M10: =IF($A10="","",IFERROR(IF(INDEX(tblCostos[Transporte unitario],MATCH($A10,tblCostos[SKU],0))="","",INDEX(tblCostos[Transporte unitario],MATCH($A10,tblCostos[SKU],0))),"")) | N10: =IF($A10="","",IFERROR(IF(INDEX(tblCostos[Impuestos / aranceles unitarios],MATCH($A10,tblCostos[SKU],0))="","",INDEX(tblCostos[Impuestos / aranceles unitarios],MATCH($A10,tblCostos[SKU],0))),"")) | O10: =IF($A10="","",IFERROR(IF(INDEX(tblCostos[Empaque unitario],MATCH($A10,tblCostos[SKU],0))="","",INDEX(tblCostos[Empaque unitario],MATCH($A10,tblCostos[SKU],0))),"")) | P10: =IF($A10="","",IFERROR(IF(INDEX(tblCostos[Otros costos variables unitarios],MATCH($A10,tblCostos[SKU],0))="","",INDEX(tblCostos[Otros costos variables unitarios],MATCH($A10,tblCostos[SKU],0))),"")) | Q10: =IF($A10="","",IFERROR(IF(INDEX(tblCostos[COSTO REAL UNITARIO],MATCH($A10,tblCostos[SKU],0))="","PENDIENTE",INDEX(tblCostos[COSTO REAL UNITARIO],MATCH($A10,tblCostos[SKU],0))),"PENDIENTE")) | R10: =IF($A10="","",IFERROR(IF(INDEX(tblCostos[Costo variable de venta unitario],MATCH($A10,tblCostos[SKU],0))="","",INDEX(tblCostos[Costo variable de venta unitario],MATCH($A10,tblCostos[SKU],0))),"")) | S10: =IF($A10="","",IF(NOT(ISNUMBER($Q10)),"PENDIENTE",$Q10+IF(ISNUMBER($R10),$R10,0))) | T10: =IF($A10="","",IF(OR($K10="",NOT(ISNUMBER($K10)),NOT(ISNUMBER($Q10))),"PENDIENTE",$K10-$Q10)) | U10: =IF($A10="","",IF(OR(NOT(ISNUMBER($T10)),NOT(ISNUMBER($K10)),$K10<=0),"PENDIENTE",$T10/$K10)) | V10: =IF($A10="","",IF(OR(NOT(ISNUMBER($T10)),NOT(ISNUMBER($Q10)),$Q10<=0),"PENDIENTE",$T10/$Q10)) | W10: =IF($A10="","",IF(OR($K10="",NOT(ISNUMBER($K10)),NOT(ISNUMBER($S10))),"PENDIENTE",$K10-$S10)) | X10: =IF($A10="","",IFERROR(INDEX(tblInventario[Stock actual],MATCH($A10,tblInventario[SKU],0)),0)) | AA10: Activo | AB10: =IF($A10="","",IF(COUNTIF(tblCostos[SKU],$A10)=0,"SIN FILA EN COSTOS",IF(AND($K10="",NOT(ISNUMBER($Q10))),"FALTA PRECIO Y COSTO",IF($K10="","FALTA PRECIO",IF(NOT(ISNUMBER($Q10)),"FALTA COSTO",IF($T10<0,"MARGEN NEGATIVO",IF($T10=0,"PRECIO = COSTO","COMPLETO")))))))
A11: JAB-500 | B11: Jabón Líquido para Manos | C11: Hogar | D11: Cuidado personal | E11: 500 mL | F11: Unidad | G11: 500 | H11: Chicle, Floral, Frutas tropicales, Coco, Cherry, Fresh | J11: 60 | L11: =IF($A11="","",IFERROR(IF(INDEX(tblCostos[Costo de compra unitario],MATCH($A11,tblCostos[SKU],0))="","PENDIENTE",INDEX(tblCostos[Costo de compra unitario],MATCH($A11,tblCostos[SKU],0))),"PENDIENTE")) | M11: =IF($A11="","",IFERROR(IF(INDEX(tblCostos[Transporte unitario],MATCH($A11,tblCostos[SKU],0))="","",INDEX(tblCostos[Transporte unitario],MATCH($A11,tblCostos[SKU],0))),"")) | N11: =IF($A11="","",IFERROR(IF(INDEX(tblCostos[Impuestos / aranceles unitarios],MATCH($A11,tblCostos[SKU],0))="","",INDEX(tblCostos[Impuestos / aranceles unitarios],MATCH($A11,tblCostos[SKU],0))),"")) | O11: =IF($A11="","",IFERROR(IF(INDEX(tblCostos[Empaque unitario],MATCH($A11,tblCostos[SKU],0))="","",INDEX(tblCostos[Empaque unitario],MATCH($A11,tblCostos[SKU],0))),"")) | P11: =IF($A11="","",IFERROR(IF(INDEX(tblCostos[Otros costos variables unitarios],MATCH($A11,tblCostos[SKU],0))="","",INDEX(tblCostos[Otros costos variables unitarios],MATCH($A11,tblCostos[SKU],0))),"")) | Q11: =IF($A11="","",IFERROR(IF(INDEX(tblCostos[COSTO REAL UNITARIO],MATCH($A11,tblCostos[SKU],0))="","PENDIENTE",INDEX(tblCostos[COSTO REAL UNITARIO],MATCH($A11,tblCostos[SKU],0))),"PENDIENTE")) | R11: =IF($A11="","",IFERROR(IF(INDEX(tblCostos[Costo variable de venta unitario],MATCH($A11,tblCostos[SKU],0))="","",INDEX(tblCostos[Costo variable de venta unitario],MATCH($A11,tblCostos[SKU],0))),"")) | S11: =IF($A11="","",IF(NOT(ISNUMBER($Q11)),"PENDIENTE",$Q11+IF(ISNUMBER($R11),$R11,0))) | T11: =IF($A11="","",IF(OR($K11="",NOT(ISNUMBER($K11)),NOT(ISNUMBER($Q11))),"PENDIENTE",$K11-$Q11)) | U11: =IF($A11="","",IF(OR(NOT(ISNUMBER($T11)),NOT(ISNUMBER($K11)),$K11<=0),"PENDIENTE",$T11/$K11)) | V11: =IF($A11="","",IF(OR(NOT(ISNUMBER($T11)),NOT(ISNUMBER($Q11)),$Q11<=0),"PENDIENTE",$T11/$Q11)) | W11: =IF($A11="","",IF(OR($K11="",NOT(ISNUMBER($K11)),NOT(ISNUMBER($S11))),"PENDIENTE",$K11-$S11)) | X11: =IF($A11="","",IFERROR(INDEX(tblInventario[Stock actual],MATCH($A11,tblInventario[SKU],0)),0)) | AA11: Activo | AB11: =IF($A11="","",IF(COUNTIF(tblCostos[SKU],$A11)=0,"SIN FILA EN COSTOS",IF(AND($K11="",NOT(ISNUMBER($Q11))),"FALTA PRECIO Y COSTO",IF($K11="","FALTA PRECIO",IF(NOT(ISNUMBER($Q11)),"FALTA COSTO",IF($T11<0,"MARGEN NEGATIVO",IF($T11=0,"PRECIO = COSTO","COMPLETO")))))))
A12: JAB-2L | B12: Jabón Líquido para Manos | C12: Hogar | D12: Cuidado personal | E12: 2 Litros | F12: Unidad | G12: 2000 | H12: Chicle, Floral, Frutas tropicales, Coco, Cherry, Fresh | J12: 100 | L12: =IF($A12="","",IFERROR(IF(INDEX(tblCostos[Costo de compra unitario],MATCH($A12,tblCostos[SKU],0))="","PENDIENTE",INDEX(tblCostos[Costo de compra unitario],MATCH($A12,tblCostos[SKU],0))),"PENDIENTE")) | M12: =IF($A12="","",IFERROR(IF(INDEX(tblCostos[Transporte unitario],MATCH($A12,tblCostos[SKU],0))="","",INDEX(tblCostos[Transporte unitario],MATCH($A12,tblCostos[SKU],0))),"")) | N12: =IF($A12="","",IFERROR(IF(INDEX(tblCostos[Impuestos / aranceles unitarios],MATCH($A12,tblCostos[SKU],0))="","",INDEX(tblCostos[Impuestos / aranceles unitarios],MATCH($A12,tblCostos[SKU],0))),"")) | O12: =IF($A12="","",IFERROR(IF(INDEX(tblCostos[Empaque unitario],MATCH($A12,tblCostos[SKU],0))="","",INDEX(tblCostos[Empaque unitario],MATCH($A12,tblCostos[SKU],0))),"")) | P12: =IF($A12="","",IFERROR(IF(INDEX(tblCostos[Otros costos variables unitarios],MATCH($A12,tblCostos[SKU],0))="","",INDEX(tblCostos[Otros costos variables unitarios],MATCH($A12,tblCostos[SKU],0))),"")) | Q12: =IF($A12="","",IFERROR(IF(INDEX(tblCostos[COSTO REAL UNITARIO],MATCH($A12,tblCostos[SKU],0))="","PENDIENTE",INDEX(tblCostos[COSTO REAL UNITARIO],MATCH($A12,tblCostos[SKU],0))),"PENDIENTE")) | R12: =IF($A12="","",IFERROR(IF(INDEX(tblCostos[Costo variable de venta unitario],MATCH($A12,tblCostos[SKU],0))="","",INDEX(tblCostos[Costo variable de venta unitario],MATCH($A12,tblCostos[SKU],0))),"")) | S12: =IF($A12="","",IF(NOT(ISNUMBER($Q12)),"PENDIENTE",$Q12+IF(ISNUMBER($R12),$R12,0))) | T12: =IF($A12="","",IF(OR($K12="",NOT(ISNUMBER($K12)),NOT(ISNUMBER($Q12))),"PENDIENTE",$K12-$Q12)) | U12: =IF($A12="","",IF(OR(NOT(ISNUMBER($T12)),NOT(ISNUMBER($K12)),$K12<=0),"PENDIENTE",$T12/$K12)) | V12: =IF($A12="","",IF(OR(NOT(ISNUMBER($T12)),NOT(ISNUMBER($Q12)),$Q12<=0),"PENDIENTE",$T12/$Q12)) | W12: =IF($A12="","",IF(OR($K12="",NOT(ISNUMBER($K12)),NOT(ISNUMBER($S12))),"PENDIENTE",$K12-$S12)) | X12: =IF($A12="","",IFERROR(INDEX(tblInventario[Stock actual],MATCH($A12,tblInventario[SKU],0)),0)) | AA12: Activo | AB12: =IF($A12="","",IF(COUNTIF(tblCostos[SKU],$A12)=0,"SIN FILA EN COSTOS",IF(AND($K12="",NOT(ISNUMBER($Q12))),"FALTA PRECIO Y COSTO",IF($K12="","FALTA PRECIO",IF(NOT(ISNUMBER($Q12)),"FALTA COSTO",IF($T12<0,"MARGEN NEGATIVO",IF($T12=0,"PRECIO = COSTO","COMPLETO")))))))
A13: JAB-GAL | B13: Jabón Líquido para Manos | C13: Hogar | D13: Cuidado personal | E13: Galón | F13: Unidad | G13: 3785 | H13: Chicle, Floral, Frutas tropicales, Coco, Cherry, Fresh | J13: 150 | L13: =IF($A13="","",IFERROR(IF(INDEX(tblCostos[Costo de compra unitario],MATCH($A13,tblCostos[SKU],0))="","PENDIENTE",INDEX(tblCostos[Costo de compra unitario],MATCH($A13,tblCostos[SKU],0))),"PENDIENTE")) | M13: =IF($A13="","",IFERROR(IF(INDEX(tblCostos[Transporte unitario],MATCH($A13,tblCostos[SKU],0))="","",INDEX(tblCostos[Transporte unitario],MATCH($A13,tblCostos[SKU],0))),"")) | N13: =IF($A13="","",IFERROR(IF(INDEX(tblCostos[Impuestos / aranceles unitarios],MATCH($A13,tblCostos[SKU],0))="","",INDEX(tblCostos[Impuestos / aranceles unitarios],MATCH($A13,tblCostos[SKU],0))),"")) | O13: =IF($A13="","",IFERROR(IF(INDEX(tblCostos[Empaque unitario],MATCH($A13,tblCostos[SKU],0))="","",INDEX(tblCostos[Empaque unitario],MATCH($A13,tblCostos[SKU],0))),"")) | P13: =IF($A13="","",IFERROR(IF(INDEX(tblCostos[Otros costos variables unitarios],MATCH($A13,tblCostos[SKU],0))="","",INDEX(tblCostos[Otros costos variables unitarios],MATCH($A13,tblCostos[SKU],0))),"")) | Q13: =IF($A13="","",IFERROR(IF(INDEX(tblCostos[COSTO REAL UNITARIO],MATCH($A13,tblCostos[SKU],0))="","PENDIENTE",INDEX(tblCostos[COSTO REAL UNITARIO],MATCH($A13,tblCostos[SKU],0))),"PENDIENTE")) | R13: =IF($A13="","",IFERROR(IF(INDEX(tblCostos[Costo variable de venta unitario],MATCH($A13,tblCostos[SKU],0))="","",INDEX(tblCostos[Costo variable de venta unitario],MATCH($A13,tblCostos[SKU],0))),"")) | S13: =IF($A13="","",IF(NOT(ISNUMBER($Q13)),"PENDIENTE",$Q13+IF(ISNUMBER($R13),$R13,0))) | T13: =IF($A13="","",IF(OR($K13="",NOT(ISNUMBER($K13)),NOT(ISNUMBER($Q13))),"PENDIENTE",$K13-$Q13)) | U13: =IF($A13="","",IF(OR(NOT(ISNUMBER($T13)),NOT(ISNUMBER($K13)),$K13<=0),"PENDIENTE",$T13/$K13)) | V13: =IF($A13="","",IF(OR(NOT(ISNUMBER($T13)),NOT(ISNUMBER($Q13)),$Q13<=0),"PENDIENTE",$T13/$Q13)) | W13: =IF($A13="","",IF(OR($K13="",NOT(ISNUMBER($K13)),NOT(ISNUMBER($S13))),"PENDIENTE",$K13-$S13)) | X13: =IF($A13="","",IFERROR(INDEX(tblInventario[Stock actual],MATCH($A13,tblInventario[SKU],0)),0)) | AA13: Activo | AB13: =IF($A13="","",IF(COUNTIF(tblCostos[SKU],$A13)=0,"SIN FILA EN COSTOS",IF(AND($K13="",NOT(ISNUMBER($Q13))),"FALTA PRECIO Y COSTO",IF($K13="","FALTA PRECIO",IF(NOT(ISNUMBER($Q13)),"FALTA COSTO",IF($T13<0,"MARGEN NEGATIVO",IF($T13=0,"PRECIO = COSTO","COMPLETO")))))))
A14: SUA-GAL | B14: Suavizante sin Enjuague | C14: Lavandería | D14: Suavizantes | E14: Galón | F14: Unidad | G14: 3785 | H14: Floral | J14: 130 | L14: =IF($A14="","",IFERROR(IF(INDEX(tblCostos[Costo de compra unitario],MATCH($A14,tblCostos[SKU],0))="","PENDIENTE",INDEX(tblCostos[Costo de compra unitario],MATCH($A14,tblCostos[SKU],0))),"PENDIENTE")) | M14: =IF($A14="","",IFERROR(IF(INDEX(tblCostos[Transporte unitario],MATCH($A14,tblCostos[SKU],0))="","",INDEX(tblCostos[Transporte unitario],MATCH($A14,tblCostos[SKU],0))),"")) | N14: =IF($A14="","",IFERROR(IF(INDEX(tblCostos[Impuestos / aranceles unitarios],MATCH($A14,tblCostos[SKU],0))="","",INDEX(tblCostos[Impuestos / aranceles unitarios],MATCH($A14,tblCostos[SKU],0))),"")) | O14: =IF($A14="","",IFERROR(IF(INDEX(tblCostos[Empaque unitario],MATCH($A14,tblCostos[SKU],0))="","",INDEX(tblCostos[Empaque unitario],MATCH($A14,tblCostos[SKU],0))),"")) | P14: =IF($A14="","",IFERROR(IF(INDEX(tblCostos[Otros costos variables unitarios],MATCH($A14,tblCostos[SKU],0))="","",INDEX(tblCostos[Otros costos variables unitarios],MATCH($A14,tblCostos[SKU],0))),"")) | Q14: =IF($A14="","",IFERROR(IF(INDEX(tblCostos[COSTO REAL UNITARIO],MATCH($A14,tblCostos[SKU],0))="","PENDIENTE",INDEX(tblCostos[COSTO REAL UNITARIO],MATCH($A14,tblCostos[SKU],0))),"PENDIENTE")) | R14: =IF($A14="","",IFERROR(IF(INDEX(tblCostos[Costo variable de venta unitario],MATCH($A14,tblCostos[SKU],0))="","",INDEX(tblCostos[Costo variable de venta unitario],MATCH($A14,tblCostos[SKU],0))),"")) | S14: =IF($A14="","",IF(NOT(ISNUMBER($Q14)),"PENDIENTE",$Q14+IF(ISNUMBER($R14),$R14,0))) | T14: =IF($A14="","",IF(OR($K14="",NOT(ISNUMBER($K14)),NOT(ISNUMBER($Q14))),"PENDIENTE",$K14-$Q14)) | U14: =IF($A14="","",IF(OR(NOT(ISNUMBER($T14)),NOT(ISNUMBER($K14)),$K14<=0),"PENDIENTE",$T14/$K14)) | V14: =IF($A14="","",IF(OR(NOT(ISNUMBER($T14)),NOT(ISNUMBER($Q14)),$Q14<=0),"PENDIENTE",$T14/$Q14)) | W14: =IF($A14="","",IF(OR($K14="",NOT(ISNUMBER($K14)),NOT(ISNUMBER($S14))),"PENDIENTE",$K14-$S14)) | X14: =IF($A14="","",IFERROR(INDEX(tblInventario[Stock actual],MATCH($A14,tblInventario[SKU],0)),0)) | AA14: Activo | AB14: =IF($A14="","",IF(COUNTIF(tblCostos[SKU],$A14)=0,"SIN FILA EN COSTOS",IF(AND($K14="",NOT(ISNUMBER($Q14))),"FALTA PRECIO Y COSTO",IF($K14="","FALTA PRECIO",IF(NOT(ISNUMBER($Q14)),"FALTA COSTO",IF($T14<0,"MARGEN NEGATIVO",IF($T14=0,"PRECIO = COSTO","COMPLETO")))))))
A15: DET-GAL | B15: Detergente Líquido para Lavadora | C15: Lavandería | D15: Detergentes | E15: Galón | F15: Unidad | G15: 3785 | H15: Floral | J15: 140 | L15: =IF($A15="","",IFERROR(IF(INDEX(tblCostos[Costo de compra unitario],MATCH($A15,tblCostos[SKU],0))="","PENDIENTE",INDEX(tblCostos[Costo de compra unitario],MATCH($A15,tblCostos[SKU],0))),"PENDIENTE")) | M15: =IF($A15="","",IFERROR(IF(INDEX(tblCostos[Transporte unitario],MATCH($A15,tblCostos[SKU],0))="","",INDEX(tblCostos[Transporte unitario],MATCH($A15,tblCostos[SKU],0))),"")) | N15: =IF($A15="","",IFERROR(IF(INDEX(tblCostos[Impuestos / aranceles unitarios],MATCH($A15,tblCostos[SKU],0))="","",INDEX(tblCostos[Impuestos / aranceles unitarios],MATCH($A15,tblCostos[SKU],0))),"")) | O15: =IF($A15="","",IFERROR(IF(INDEX(tblCostos[Empaque unitario],MATCH($A15,tblCostos[SKU],0))="","",INDEX(tblCostos[Empaque unitario],MATCH($A15,tblCostos[SKU],0))),"")) | P15: =IF($A15="","",IFERROR(IF(INDEX(tblCostos[Otros costos variables unitarios],MATCH($A15,tblCostos[SKU],0))="","",INDEX(tblCostos[Otros costos variables unitarios],MATCH($A15,tblCostos[SKU],0))),"")) | Q15: =IF($A15="","",IFERROR(IF(INDEX(tblCostos[COSTO REAL UNITARIO],MATCH($A15,tblCostos[SKU],0))="","PENDIENTE",INDEX(tblCostos[COSTO REAL UNITARIO],MATCH($A15,tblCostos[SKU],0))),"PENDIENTE")) | R15: =IF($A15="","",IFERROR(IF(INDEX(tblCostos[Costo variable de venta unitario],MATCH($A15,tblCostos[SKU],0))="","",INDEX(tblCostos[Costo variable de venta unitario],MATCH($A15,tblCostos[SKU],0))),"")) | S15: =IF($A15="","",IF(NOT(ISNUMBER($Q15)),"PENDIENTE",$Q15+IF(ISNUMBER($R15),$R15,0))) | T15: =IF($A15="","",IF(OR($K15="",NOT(ISNUMBER($K15)),NOT(ISNUMBER($Q15))),"PENDIENTE",$K15-$Q15)) | U15: =IF($A15="","",IF(OR(NOT(ISNUMBER($T15)),NOT(ISNUMBER($K15)),$K15<=0),"PENDIENTE",$T15/$K15)) | V15: =IF($A15="","",IF(OR(NOT(ISNUMBER($T15)),NOT(ISNUMBER($Q15)),$Q15<=0),"PENDIENTE",$T15/$Q15)) | W15: =IF($A15="","",IF(OR($K15="",NOT(ISNUMBER($K15)),NOT(ISNUMBER($S15))),"PENDIENTE",$K15-$S15)) | X15: =IF($A15="","",IFERROR(INDEX(tblInventario[Stock actual],MATCH($A15,tblInventario[SKU],0)),0)) | AA15: Activo | AB15: =IF($A15="","",IF(COUNTIF(tblCostos[SKU],$A15)=0,"SIN FILA EN COSTOS",IF(AND($K15="",NOT(ISNUMBER($Q15))),"FALTA PRECIO Y COSTO",IF($K15="","FALTA PRECIO",IF(NOT(ISNUMBER($Q15)),"FALTA COSTO",IF($T15<0,"MARGEN NEGATIVO",IF($T15=0,"PRECIO = COSTO","COMPLETO")))))))
A16: VID-750 | B16: Limpiador de Vidrios | C16: Limpieza Hogar | D16: Vidrios y cristales | E16: 750 mL | F16: Unidad | G16: 750 | H16: Sin aroma específico | J16: 60 | L16: =IF($A16="","",IFERROR(IF(INDEX(tblCostos[Costo de compra unitario],MATCH($A16,tblCostos[SKU],0))="","PENDIENTE",INDEX(tblCostos[Costo de compra unitario],MATCH($A16,tblCostos[SKU],0))),"PENDIENTE")) | M16: =IF($A16="","",IFERROR(IF(INDEX(tblCostos[Transporte unitario],MATCH($A16,tblCostos[SKU],0))="","",INDEX(tblCostos[Transporte unitario],MATCH($A16,tblCostos[SKU],0))),"")) | N16: =IF($A16="","",IFERROR(IF(INDEX(tblCostos[Impuestos / aranceles unitarios],MATCH($A16,tblCostos[SKU],0))="","",INDEX(tblCostos[Impuestos / aranceles unitarios],MATCH($A16,tblCostos[SKU],0))),"")) | O16: =IF($A16="","",IFERROR(IF(INDEX(tblCostos[Empaque unitario],MATCH($A16,tblCostos[SKU],0))="","",INDEX(tblCostos[Empaque unitario],MATCH($A16,tblCostos[SKU],0))),"")) | P16: =IF($A16="","",IFERROR(IF(INDEX(tblCostos[Otros costos variables unitarios],MATCH($A16,tblCostos[SKU],0))="","",INDEX(tblCostos[Otros costos variables unitarios],MATCH($A16,tblCostos[SKU],0))),"")) | Q16: =IF($A16="","",IFERROR(IF(INDEX(tblCostos[COSTO REAL UNITARIO],MATCH($A16,tblCostos[SKU],0))="","PENDIENTE",INDEX(tblCostos[COSTO REAL UNITARIO],MATCH($A16,tblCostos[SKU],0))),"PENDIENTE")) | R16: =IF($A16="","",IFERROR(IF(INDEX(tblCostos[Costo variable de venta unitario],MATCH($A16,tblCostos[SKU],0))="","",INDEX(tblCostos[Costo variable de venta unitario],MATCH($A16,tblCostos[SKU],0))),"")) | S16: =IF($A16="","",IF(NOT(ISNUMBER($Q16)),"PENDIENTE",$Q16+IF(ISNUMBER($R16),$R16,0))) | T16: =IF($A16="","",IF(OR($K16="",NOT(ISNUMBER($K16)),NOT(ISNUMBER($Q16))),"PENDIENTE",$K16-$Q16)) | U16: =IF($A16="","",IF(OR(NOT(ISNUMBER($T16)),NOT(ISNUMBER($K16)),$K16<=0),"PENDIENTE",$T16/$K16)) | V16: =IF($A16="","",IF(OR(NOT(ISNUMBER($T16)),NOT(ISNUMBER($Q16)),$Q16<=0),"PENDIENTE",$T16/$Q16)) | W16: =IF($A16="","",IF(OR($K16="",NOT(ISNUMBER($K16)),NOT(ISNUMBER($S16))),"PENDIENTE",$K16-$S16)) | X16: =IF($A16="","",IFERROR(INDEX(tblInventario[Stock actual],MATCH($A16,tblInventario[SKU],0)),0)) | AA16: Activo | AB16: =IF($A16="","",IF(COUNTIF(tblCostos[SKU],$A16)=0,"SIN FILA EN COSTOS",IF(AND($K16="",NOT(ISNUMBER($Q16))),"FALTA PRECIO Y COSTO",IF($K16="","FALTA PRECIO",IF(NOT(ISNUMBER($Q16)),"FALTA COSTO",IF($T16<0,"MARGEN NEGATIVO",IF($T16=0,"PRECIO = COSTO","COMPLETO")))))))
A17: VID-GAL | B17: Limpiador de Vidrios | C17: Limpieza Hogar | D17: Vidrios y cristales | E17: Galón | F17: Unidad | G17: 3785 | H17: Sin aroma específico | J17: 120 | L17: =IF($A17="","",IFERROR(IF(INDEX(tblCostos[Costo de compra unitario],MATCH($A17,tblCostos[SKU],0))="","PENDIENTE",INDEX(tblCostos[Costo de compra unitario],MATCH($A17,tblCostos[SKU],0))),"PENDIENTE")) | M17: =IF($A17="","",IFERROR(IF(INDEX(tblCostos[Transporte unitario],MATCH($A17,tblCostos[SKU],0))="","",INDEX(tblCostos[Transporte unitario],MATCH($A17,tblCostos[SKU],0))),"")) | N17: =IF($A17="","",IFERROR(IF(INDEX(tblCostos[Impuestos / aranceles unitarios],MATCH($A17,tblCostos[SKU],0))="","",INDEX(tblCostos[Impuestos / aranceles unitarios],MATCH($A17,tblCostos[SKU],0))),"")) | O17: =IF($A17="","",IFERROR(IF(INDEX(tblCostos[Empaque unitario],MATCH($A17,tblCostos[SKU],0))="","",INDEX(tblCostos[Empaque unitario],MATCH($A17,tblCostos[SKU],0))),"")) | P17: =IF($A17="","",IFERROR(IF(INDEX(tblCostos[Otros costos variables unitarios],MATCH($A17,tblCostos[SKU],0))="","",INDEX(tblCostos[Otros costos variables unitarios],MATCH($A17,tblCostos[SKU],0))),"")) | Q17: =IF($A17="","",IFERROR(IF(INDEX(tblCostos[COSTO REAL UNITARIO],MATCH($A17,tblCostos[SKU],0))="","PENDIENTE",INDEX(tblCostos[COSTO REAL UNITARIO],MATCH($A17,tblCostos[SKU],0))),"PENDIENTE")) | R17: =IF($A17="","",IFERROR(IF(INDEX(tblCostos[Costo variable de venta unitario],MATCH($A17,tblCostos[SKU],0))="","",INDEX(tblCostos[Costo variable de venta unitario],MATCH($A17,tblCostos[SKU],0))),"")) | S17: =IF($A17="","",IF(NOT(ISNUMBER($Q17)),"PENDIENTE",$Q17+IF(ISNUMBER($R17),$R17,0))) | T17: =IF($A17="","",IF(OR($K17="",NOT(ISNUMBER($K17)),NOT(ISNUMBER($Q17))),"PENDIENTE",$K17-$Q17)) | U17: =IF($A17="","",IF(OR(NOT(ISNUMBER($T17)),NOT(ISNUMBER($K17)),$K17<=0),"PENDIENTE",$T17/$K17)) | V17: =IF($A17="","",IF(OR(NOT(ISNUMBER($T17)),NOT(ISNUMBER($Q17)),$Q17<=0),"PENDIENTE",$T17/$Q17)) | W17: =IF($A17="","",IF(OR($K17="",NOT(ISNUMBER($K17)),NOT(ISNUMBER($S17))),"PENDIENTE",$K17-$S17)) | X17: =IF($A17="","",IFERROR(INDEX(tblInventario[Stock actual],MATCH($A17,tblInventario[SKU],0)),0)) | AA17: Activo | AB17: =IF($A17="","",IF(COUNTIF(tblCostos[SKU],$A17)=0,"SIN FILA EN COSTOS",IF(AND($K17="",NOT(ISNUMBER($Q17))),"FALTA PRECIO Y COSTO",IF($K17="","FALTA PRECIO",IF(NOT(ISNUMBER($Q17)),"FALTA COSTO",IF($T17<0,"MARGEN NEGATIVO",IF($T17=0,"PRECIO = COSTO","COMPLETO")))))))
A18: LAV-500 | B18: Deterlente Lavaplatos | C18: Limpieza Hogar | D18: Cocina | E18: 500 mL | F18: Unidad | G18: 500 | H18: Limón | J18: 50 | L18: =IF($A18="","",IFERROR(IF(INDEX(tblCostos[Costo de compra unitario],MATCH($A18,tblCostos[SKU],0))="","PENDIENTE",INDEX(tblCostos[Costo de compra unitario],MATCH($A18,tblCostos[SKU],0))),"PENDIENTE")) | M18: =IF($A18="","",IFERROR(IF(INDEX(tblCostos[Transporte unitario],MATCH($A18,tblCostos[SKU],0))="","",INDEX(tblCostos[Transporte unitario],MATCH($A18,tblCostos[SKU],0))),"")) | N18: =IF($A18="","",IFERROR(IF(INDEX(tblCostos[Impuestos / aranceles unitarios],MATCH($A18,tblCostos[SKU],0))="","",INDEX(tblCostos[Impuestos / aranceles unitarios],MATCH($A18,tblCostos[SKU],0))),"")) | O18: =IF($A18="","",IFERROR(IF(INDEX(tblCostos[Empaque unitario],MATCH($A18,tblCostos[SKU],0))="","",INDEX(tblCostos[Empaque unitario],MATCH($A18,tblCostos[SKU],0))),"")) | P18: =IF($A18="","",IFERROR(IF(INDEX(tblCostos[Otros costos variables unitarios],MATCH($A18,tblCostos[SKU],0))="","",INDEX(tblCostos[Otros costos variables unitarios],MATCH($A18,tblCostos[SKU],0))),"")) | Q18: =IF($A18="","",IFERROR(IF(INDEX(tblCostos[COSTO REAL UNITARIO],MATCH($A18,tblCostos[SKU],0))="","PENDIENTE",INDEX(tblCostos[COSTO REAL UNITARIO],MATCH($A18,tblCostos[SKU],0))),"PENDIENTE")) | R18: =IF($A18="","",IFERROR(IF(INDEX(tblCostos[Costo variable de venta unitario],MATCH($A18,tblCostos[SKU],0))="","",INDEX(tblCostos[Costo variable de venta unitario],MATCH($A18,tblCostos[SKU],0))),"")) | S18: =IF($A18="","",IF(NOT(ISNUMBER($Q18)),"PENDIENTE",$Q18+IF(ISNUMBER($R18),$R18,0))) | T18: =IF($A18="","",IF(OR($K18="",NOT(ISNUMBER($K18)),NOT(ISNUMBER($Q18))),"PENDIENTE",$K18-$Q18)) | U18: =IF($A18="","",IF(OR(NOT(ISNUMBER($T18)),NOT(ISNUMBER($K18)),$K18<=0),"PENDIENTE",$T18/$K18)) | V18: =IF($A18="","",IF(OR(NOT(ISNUMBER($T18)),NOT(ISNUMBER($Q18)),$Q18<=0),"PENDIENTE",$T18/$Q18)) | W18: =IF($A18="","",IF(OR($K18="",NOT(ISNUMBER($K18)),NOT(ISNUMBER($S18))),"PENDIENTE",$K18-$S18)) | X18: =IF($A18="","",IFERROR(INDEX(tblInventario[Stock actual],MATCH($A18,tblInventario[SKU],0)),0)) | AA18: Activo | AB18: =IF($A18="","",IF(COUNTIF(tblCostos[SKU],$A18)=0,"SIN FILA EN COSTOS",IF(AND($K18="",NOT(ISNUMBER($Q18))),"FALTA PRECIO Y COSTO",IF($K18="","FALTA PRECIO",IF(NOT(ISNUMBER($Q18)),"FALTA COSTO",IF($T18<0,"MARGEN NEGATIVO",IF($T18=0,"PRECIO = COSTO","COMPLETO")))))))
... A39: PLL-710 | B39: Puli-Llanta en Crema | C39: Automotriz | D39: Abrillantadores | E39: 710 mL | F39: Unidad | G39: 710 | H39: Original | J39: 75 | L39: =IF($A39="","",IFERROR(IF(INDEX(tblCostos[Costo de compra unitario],MATCH($A39,tblCostos[SKU],0))="","PENDIENTE",INDEX(tblCostos[Costo de compra unitario],MATCH($A39,tblCostos[SKU],0))),"PENDIENTE")) | M39: =IF($A39="","",IFERROR(IF(INDEX(tblCostos[Transporte unitario],MATCH($A39,tblCostos[SKU],0))="","",INDEX(tblCostos[Transporte unitario],MATCH($A39,tblCostos[SKU],0))),"")) | N39: =IF($A39="","",IFERROR(IF(INDEX(tblCostos[Impuestos / aranceles unitarios],MATCH($A39,tblCostos[SKU],0))="","",INDEX(tblCostos[Impuestos / aranceles unitarios],MATCH($A39,tblCostos[SKU],0))),"")) | O39: =IF($A39="","",IFERROR(IF(INDEX(tblCostos[Empaque unitario],MATCH($A39,tblCostos[SKU],0))="","",INDEX(tblCostos[Empaque unitario],MATCH($A39,tblCostos[SKU],0))),"")) | P39: =IF($A39="","",IFERROR(IF(INDEX(tblCostos[Otros costos variables unitarios],MATCH($A39,tblCostos[SKU],0))="","",INDEX(tblCostos[Otros costos variables unitarios],MATCH($A39,tblCostos[SKU],0))),"")) | Q39: =IF($A39="","",IFERROR(IF(INDEX(tblCostos[COSTO REAL UNITARIO],MATCH($A39,tblCostos[SKU],0))="","PENDIENTE",INDEX(tblCostos[COSTO REAL UNITARIO],MATCH($A39,tblCostos[SKU],0))),"PENDIENTE")) | R39: =IF($A39="","",IFERROR(IF(INDEX(tblCostos[Costo variable de venta unitario],MATCH($A39,tblCostos[SKU],0))="","",INDEX(tblCostos[Costo variable de venta unitario],MATCH($A39,tblCostos[SKU],0))),"")) | S39: =IF($A39="","",IF(NOT(ISNUMBER($Q39)),"PENDIENTE",$Q39+IF(ISNUMBER($R39),$R39,0))) | T39: =IF($A39="","",IF(OR($K39="",NOT(ISNUMBER($K39)),NOT(ISNUMBER($Q39))),"PENDIENTE",$K39-$Q39)) | U39: =IF($A39="","",IF(OR(NOT(ISNUMBER($T39)),NOT(ISNUMBER($K39)),$K39<=0),"PENDIENTE",$T39/$K39)) | V39: =IF($A39="","",IF(OR(NOT(ISNUMBER($T39)),NOT(ISNUMBER($Q39)),$Q39<=0),"PENDIENTE",$T39/$Q39)) | W39: =IF($A39="","",IF(OR($K39="",NOT(ISNUMBER($K39)),NOT(ISNUMBER($S39))),"PENDIENTE",$K39-$S39)) | X39: =IF($A39="","",IFERROR(INDEX(tblInventario[Stock actual],MATCH($A39,tblInventario[SKU],0)),0)) | AA39: Activo | AB39: =IF($A39="","",IF(COUNTIF(tblCostos[SKU],$A39)=0,"SIN FILA EN COSTOS",IF(AND($K39="",NOT(ISNUMBER($Q39))),"FALTA PRECIO Y COSTO",IF($K39="","FALTA PRECIO",IF(NOT(ISNUMBER($Q39)),"FALTA COSTO",IF($T39<0,"MARGEN NEGATIVO",IF($T39=0,"PRECIO = COSTO","COMPLETO")))))))
A40: PLL-TAR | B40: Puli-Llanta en Crema | C40: Automotriz | D40: Abrillantadores | E40: Tarro | F40: Unidad | H40: Original | J40: 50 | L40: =IF($A40="","",IFERROR(IF(INDEX(tblCostos[Costo de compra unitario],MATCH($A40,tblCostos[SKU],0))="","PENDIENTE",INDEX(tblCostos[Costo de compra unitario],MATCH($A40,tblCostos[SKU],0))),"PENDIENTE")) | M40: =IF($A40="","",IFERROR(IF(INDEX(tblCostos[Transporte unitario],MATCH($A40,tblCostos[SKU],0))="","",INDEX(tblCostos[Transporte unitario],MATCH($A40,tblCostos[SKU],0))),"")) | N40: =IF($A40="","",IFERROR(IF(INDEX(tblCostos[Impuestos / aranceles unitarios],MATCH($A40,tblCostos[SKU],0))="","",INDEX(tblCostos[Impuestos / aranceles unitarios],MATCH($A40,tblCostos[SKU],0))),"")) | O40: =IF($A40="","",IFERROR(IF(INDEX(tblCostos[Empaque unitario],MATCH($A40,tblCostos[SKU],0))="","",INDEX(tblCostos[Empaque unitario],MATCH($A40,tblCostos[SKU],0))),"")) | P40: =IF($A40="","",IFERROR(IF(INDEX(tblCostos[Otros costos variables unitarios],MATCH($A40,tblCostos[SKU],0))="","",INDEX(tblCostos[Otros costos variables unitarios],MATCH($A40,tblCostos[SKU],0))),"")) | Q40: =IF($A40="","",IFERROR(IF(INDEX(tblCostos[COSTO REAL UNITARIO],MATCH($A40,tblCostos[SKU],0))="","PENDIENTE",INDEX(tblCostos[COSTO REAL UNITARIO],MATCH($A40,tblCostos[SKU],0))),"PENDIENTE")) | R40: =IF($A40="","",IFERROR(IF(INDEX(tblCostos[Costo variable de venta unitario],MATCH($A40,tblCostos[SKU],0))="","",INDEX(tblCostos[Costo variable de venta unitario],MATCH($A40,tblCostos[SKU],0))),"")) | S40: =IF($A40="","",IF(NOT(ISNUMBER($Q40)),"PENDIENTE",$Q40+IF(ISNUMBER($R40),$R40,0))) | T40: =IF($A40="","",IF(OR($K40="",NOT(ISNUMBER($K40)),NOT(ISNUMBER($Q40))),"PENDIENTE",$K40-$Q40)) | U40: =IF($A40="","",IF(OR(NOT(ISNUMBER($T40)),NOT(ISNUMBER($K40)),$K40<=0),"PENDIENTE",$T40/$K40)) | V40: =IF($A40="","",IF(OR(NOT(ISNUMBER($T40)),NOT(ISNUMBER($Q40)),$Q40<=0),"PENDIENTE",$T40/$Q40)) | W40: =IF($A40="","",IF(OR($K40="",NOT(ISNUMBER($K40)),NOT(ISNUMBER($S40))),"PENDIENTE",$K40-$S40)) | X40: =IF($A40="","",IFERROR(INDEX(tblInventario[Stock actual],MATCH($A40,tblInventario[SKU],0)),0)) | AA40: Activo | AB40: =IF($A40="","",IF(COUNTIF(tblCostos[SKU],$A40)=0,"SIN FILA EN COSTOS",IF(AND($K40="",NOT(ISNUMBER($Q40))),"FALTA PRECIO Y COSTO",IF($K40="","FALTA PRECIO",IF(NOT(ISNUMBER($Q40)),"FALTA COSTO",IF($T40<0,"MARGEN NEGATIVO",IF($T40=0,"PRECIO = COSTO","COMPLETO")))))))
A41: PLL-GAL | B41: Puli-Llanta en Crema | C41: Automotriz | D41: Abrillantadores | E41: Galón | F41: Unidad | G41: 3785 | H41: Original | J41: 190 | L41: =IF($A41="","",IFERROR(IF(INDEX(tblCostos[Costo de compra unitario],MATCH($A41,tblCostos[SKU],0))="","PENDIENTE",INDEX(tblCostos[Costo de compra unitario],MATCH($A41,tblCostos[SKU],0))),"PENDIENTE")) | M41: =IF($A41="","",IFERROR(IF(INDEX(tblCostos[Transporte unitario],MATCH($A41,tblCostos[SKU],0))="","",INDEX(tblCostos[Transporte unitario],MATCH($A41,tblCostos[SKU],0))),"")) | N41: =IF($A41="","",IFERROR(IF(INDEX(tblCostos[Impuestos / aranceles unitarios],MATCH($A41,tblCostos[SKU],0))="","",INDEX(tblCostos[Impuestos / aranceles unitarios],MATCH($A41,tblCostos[SKU],0))),"")) | O41: =IF($A41="","",IFERROR(IF(INDEX(tblCostos[Empaque unitario],MATCH($A41,tblCostos[SKU],0))="","",INDEX(tblCostos[Empaque unitario],MATCH($A41,tblCostos[SKU],0))),"")) | P41: =IF($A41="","",IFERROR(IF(INDEX(tblCostos[Otros costos variables unitarios],MATCH($A41,tblCostos[SKU],0))="","",INDEX(tblCostos[Otros costos variables unitarios],MATCH($A41,tblCostos[SKU],0))),"")) | Q41: =IF($A41="","",IFERROR(IF(INDEX(tblCostos[COSTO REAL UNITARIO],MATCH($A41,tblCostos[SKU],0))="","PENDIENTE",INDEX(tblCostos[COSTO REAL UNITARIO],MATCH($A41,tblCostos[SKU],0))),"PENDIENTE")) | R41: =IF($A41="","",IFERROR(IF(INDEX(tblCostos[Costo variable de venta unitario],MATCH($A41,tblCostos[SKU],0))="","",INDEX(tblCostos[Costo variable de venta unitario],MATCH($A41,tblCostos[SKU],0))),"")) | S41: =IF($A41="","",IF(NOT(ISNUMBER($Q41)),"PENDIENTE",$Q41+IF(ISNUMBER($R41),$R41,0))) | T41: =IF($A41="","",IF(OR($K41="",NOT(ISNUMBER($K41)),NOT(ISNUMBER($Q41))),"PENDIENTE",$K41-$Q41)) | U41: =IF($A41="","",IF(OR(NOT(ISNUMBER($T41)),NOT(ISNUMBER($K41)),$K41<=0),"PENDIENTE",$T41/$K41)) | V41: =IF($A41="","",IF(OR(NOT(ISNUMBER($T41)),NOT(ISNUMBER($Q41)),$Q41<=0),"PENDIENTE",$T41/$Q41)) | W41: =IF($A41="","",IF(OR($K41="",NOT(ISNUMBER($K41)),NOT(ISNUMBER($S41))),"PENDIENTE",$K41-$S41)) | X41: =IF($A41="","",IFERROR(INDEX(tblInventario[Stock actual],MATCH($A41,tblInventario[SKU],0)),0)) | AA41: Activo | AB41: =IF($A41="","",IF(COUNTIF(tblCostos[SKU],$A41)=0,"SIN FILA EN COSTOS",IF(AND($K41="",NOT(ISNUMBER($Q41))),"FALTA PRECIO Y COSTO",IF($K41="","FALTA PRECIO",IF(NOT(ISNUMBER($Q41)),"FALTA COSTO",IF($T41<0,"MARGEN NEGATIVO",IF($T41=0,"PRECIO = COSTO","COMPLETO")))))))
A42: PMA-8OZ | B42: Puli-Manos Crema Limpiadora | C42: Industrial | D42: Limpieza de manos | E42: 8 Onzas | F42: Unidad | G42: 237 | H42: Original | J42: 40 | L42: =IF($A42="","",IFERROR(IF(INDEX(tblCostos[Costo de compra unitario],MATCH($A42,tblCostos[SKU],0))="","PENDIENTE",INDEX(tblCostos[Costo de compra unitario],MATCH($A42,tblCostos[SKU],0))),"PENDIENTE")) | M42: =IF($A42="","",IFERROR(IF(INDEX(tblCostos[Transporte unitario],MATCH($A42,tblCostos[SKU],0))="","",INDEX(tblCostos[Transporte unitario],MATCH($A42,tblCostos[SKU],0))),"")) | N42: =IF($A42="","",IFERROR(IF(INDEX(tblCostos[Impuestos / aranceles unitarios],MATCH($A42,tblCostos[SKU],0))="","",INDEX(tblCostos[Impuestos / aranceles unitarios],MATCH($A42,tblCostos[SKU],0))),"")) | O42: =IF($A42="","",IFERROR(IF(INDEX(tblCostos[Empaque unitario],MATCH($A42,tblCostos[SKU],0))="","",INDEX(tblCostos[Empaque unitario],MATCH($A42,tblCostos[SKU],0))),"")) | P42: =IF($A42="","",IFERROR(IF(INDEX(tblCostos[Otros costos variables unitarios],MATCH($A42,tblCostos[SKU],0))="","",INDEX(tblCostos[Otros costos variables unitarios],MATCH($A42,tblCostos[SKU],0))),"")) | Q42: =IF($A42="","",IFERROR(IF(INDEX(tblCostos[COSTO REAL UNITARIO],MATCH($A42,tblCostos[SKU],0))="","PENDIENTE",INDEX(tblCostos[COSTO REAL UNITARIO],MATCH($A42,tblCostos[SKU],0))),"PENDIENTE")) | R42: =IF($A42="","",IFERROR(IF(INDEX(tblCostos[Costo variable de venta unitario],MATCH($A42,tblCostos[SKU],0))="","",INDEX(tblCostos[Costo variable de venta unitario],MATCH($A42,tblCostos[SKU],0))),"")) | S42: =IF($A42="","",IF(NOT(ISNUMBER($Q42)),"PENDIENTE",$Q42+IF(ISNUMBER($R42),$R42,0))) | T42: =IF($A42="","",IF(OR($K42="",NOT(ISNUMBER($K42)),NOT(ISNUMBER($Q42))),"PENDIENTE",$K42-$Q42)) | U42: =IF($A42="","",IF(OR(NOT(ISNUMBER($T42)),NOT(ISNUMBER($K42)),$K42<=0),"PENDIENTE",$T42/$K42)) | V42: =IF($A42="","",IF(OR(NOT(ISNUMBER($T42)),NOT(ISNUMBER($Q42)),$Q42<=0),"PENDIENTE",$T42/$Q42)) | W42: =IF($A42="","",IF(OR($K42="",NOT(ISNUMBER($K42)),NOT(ISNUMBER($S42))),"PENDIENTE",$K42-$S42)) | X42: =IF($A42="","",IFERROR(INDEX(tblInventario[Stock actual],MATCH($A42,tblInventario[SKU],0)),0)) | AA42: Activo | AB42: =IF($A42="","",IF(COUNTIF(tblCostos[SKU],$A42)=0,"SIN FILA EN COSTOS",IF(AND($K42="",NOT(ISNUMBER($Q42))),"FALTA PRECIO Y COSTO",IF($K42="","FALTA PRECIO",IF(NOT(ISNUMBER($Q42)),"FALTA COSTO",IF($T42<0,"MARGEN NEGATIVO",IF($T42=0,"PRECIO = COSTO","COMPLETO")))))))
A43: PMA-1L | B43: Puli-Manos Crema Limpiadora | C43: Industrial | D43: Limpieza de manos | E43: 1 Litro | F43: Unidad | G43: 1000 | H43: Original | J43: 95 | L43: =IF($A43="","",IFERROR(IF(INDEX(tblCostos[Costo de compra unitario],MATCH($A43,tblCostos[SKU],0))="","PENDIENTE",INDEX(tblCostos[Costo de compra unitario],MATCH($A43,tblCostos[SKU],0))),"PENDIENTE")) | M43: =IF($A43="","",IFERROR(IF(INDEX(tblCostos[Transporte unitario],MATCH($A43,tblCostos[SKU],0))="","",INDEX(tblCostos[Transporte unitario],MATCH($A43,tblCostos[SKU],0))),"")) | N43: =IF($A43="","",IFERROR(IF(INDEX(tblCostos[Impuestos / aranceles unitarios],MATCH($A43,tblCostos[SKU],0))="","",INDEX(tblCostos[Impuestos / aranceles unitarios],MATCH($A43,tblCostos[SKU],0))),"")) | O43: =IF($A43="","",IFERROR(IF(INDEX(tblCostos[Empaque unitario],MATCH($A43,tblCostos[SKU],0))="","",INDEX(tblCostos[Empaque unitario],MATCH($A43,tblCostos[SKU],0))),"")) | P43: =IF($A43="","",IFERROR(IF(INDEX(tblCostos[Otros costos variables unitarios],MATCH($A43,tblCostos[SKU],0))="","",INDEX(tblCostos[Otros costos variables unitarios],MATCH($A43,tblCostos[SKU],0))),"")) | Q43: =IF($A43="","",IFERROR(IF(INDEX(tblCostos[COSTO REAL UNITARIO],MATCH($A43,tblCostos[SKU],0))="","PENDIENTE",INDEX(tblCostos[COSTO REAL UNITARIO],MATCH($A43,tblCostos[SKU],0))),"PENDIENTE")) | R43: =IF($A43="","",IFERROR(IF(INDEX(tblCostos[Costo variable de venta unitario],MATCH($A43,tblCostos[SKU],0))="","",INDEX(tblCostos[Costo variable de venta unitario],MATCH($A43,tblCostos[SKU],0))),"")) | S43: =IF($A43="","",IF(NOT(ISNUMBER($Q43)),"PENDIENTE",$Q43+IF(ISNUMBER($R43),$R43,0))) | T43: =IF($A43="","",IF(OR($K43="",NOT(ISNUMBER($K43)),NOT(ISNUMBER($Q43))),"PENDIENTE",$K43-$Q43)) | U43: =IF($A43="","",IF(OR(NOT(ISNUMBER($T43)),NOT(ISNUMBER($K43)),$K43<=0),"PENDIENTE",$T43/$K43)) | V43: =IF($A43="","",IF(OR(NOT(ISNUMBER($T43)),NOT(ISNUMBER($Q43)),$Q43<=0),"PENDIENTE",$T43/$Q43)) | W43: =IF($A43="","",IF(OR($K43="",NOT(ISNUMBER($K43)),NOT(ISNUMBER($S43))),"PENDIENTE",$K43-$S43)) | X43: =IF($A43="","",IFERROR(INDEX(tblInventario[Stock actual],MATCH($A43,tblInventario[SKU],0)),0)) | AA43: Activo | AB43: =IF($A43="","",IF(COUNTIF(tblCostos[SKU],$A43)=0,"SIN FILA EN COSTOS",IF(AND($K43="",NOT(ISNUMBER($Q43))),"FALTA PRECIO Y COSTO",IF($K43="","FALTA PRECIO",IF(NOT(ISNUMBER($Q43)),"FALTA COSTO",IF($T43<0,"MARGEN NEGATIVO",IF($T43=0,"PRECIO = COSTO","COMPLETO")))))))
